{
 "cells": [
  {
   "cell_type": "code",
   "execution_count": 14,
   "id": "998af4f7",
   "metadata": {},
   "outputs": [],
   "source": [
    "import sys\n",
    "import os\n",
    "from keras.preprocessing.image import ImageDataGenerator\n",
    "from keras import optimizers\n",
    "from keras.models import Sequential\n",
    "from keras.layers import Dropout, Flatten, Dense, Activation\n",
    "from keras.layers import  Convolution2D, MaxPooling2D\n",
    "from keras import backend as K\n",
    "from keras import applications"
   ]
  },
  {
   "cell_type": "code",
   "execution_count": 33,
   "id": "69856217",
   "metadata": {},
   "outputs": [],
   "source": [
    "def modelo():\n",
    "    vgg=applications.vgg16.VGG16()\n",
    "    cnn=Sequential()\n",
    "    for capa in vgg.layers:\n",
    "        cnn.add(capa)\n",
    "    cnn.layers.pop()\n",
    "    for layer in cnn.layers:\n",
    "        layer.trainable=False\n",
    "    cnn.add(Dense(7,activation='softmax'))   \n",
    "    return cnn"
   ]
  },
  {
   "cell_type": "code",
   "execution_count": 34,
   "id": "c8034d86",
   "metadata": {},
   "outputs": [],
   "source": [
    "K.clear_session()"
   ]
  },
  {
   "cell_type": "code",
   "execution_count": 35,
   "id": "d25a7c6a",
   "metadata": {},
   "outputs": [],
   "source": [
    "data_entrenamiento = 'C:/Project/data/train'\n",
    "data_validacion = 'C:/Project/data/test'"
   ]
  },
  {
   "cell_type": "code",
   "execution_count": 44,
   "id": "9a09488f",
   "metadata": {},
   "outputs": [],
   "source": [
    "\"\"\"\n",
    "Parameters\n",
    "\"\"\"\n",
    "epocas=20\n",
    "longitud, altura = 150, 150\n",
    "batch_size = 32\n",
    "pasos = 50\n",
    "validation_steps = 300\n",
    "filtrosConv1 = 32\n",
    "filtrosConv2 = 64\n",
    "tamano_filtro1 = (3, 3)\n",
    "tamano_filtro2 = (2, 2)\n",
    "tamano_pool = (2, 2)\n",
    "clases = 7\n",
    "lr = 0.0004"
   ]
  },
  {
   "cell_type": "code",
   "execution_count": 45,
   "id": "8906b297",
   "metadata": {},
   "outputs": [
    {
     "name": "stdout",
     "output_type": "stream",
     "text": [
      "Found 1633 images belonging to 7 classes.\n",
      "Found 809 images belonging to 7 classes.\n"
     ]
    }
   ],
   "source": [
    "##Preparamos nuestras imagenes\n",
    "\n",
    "entrenamiento_datagen = ImageDataGenerator(\n",
    "    rescale=1. / 255,\n",
    "    shear_range=0.2,\n",
    "    zoom_range=0.2,\n",
    "    horizontal_flip=True)\n",
    "\n",
    "test_datagen = ImageDataGenerator(rescale=1. / 255)\n",
    "\n",
    "entrenamiento_generador = entrenamiento_datagen.flow_from_directory(\n",
    "    data_entrenamiento,\n",
    "    target_size=(altura, longitud),\n",
    "    batch_size=batch_size,\n",
    "    class_mode='categorical')\n",
    "\n",
    "validacion_generador = test_datagen.flow_from_directory(\n",
    "    data_validacion,\n",
    "    target_size=(altura, longitud),\n",
    "    batch_size=batch_size,\n",
    "    class_mode='categorical')"
   ]
  },
  {
   "cell_type": "code",
   "execution_count": 46,
   "id": "0ff5e66a",
   "metadata": {},
   "outputs": [],
   "source": [
    "cnn = modelo()"
   ]
  },
  {
   "cell_type": "code",
   "execution_count": 47,
   "id": "012d3a90",
   "metadata": {},
   "outputs": [],
   "source": [
    "cnn.compile(loss='categorical_crossentropy',\n",
    "            optimizer=optimizers.Adam(learning_rate=lr),\n",
    "            metrics=['accuracy'])"
   ]
  },
  {
   "cell_type": "code",
   "execution_count": 48,
   "id": "907deb9a",
   "metadata": {},
   "outputs": [
    {
     "name": "stdout",
     "output_type": "stream",
     "text": [
      "Epoch 1/20\n"
     ]
    },
    {
     "ename": "InvalidArgumentError",
     "evalue": "Graph execution error:\n\nDetected at node 'sequential_1/flatten/Reshape' defined at (most recent call last):\n    File \"C:\\Users\\Usuario\\anaconda3\\lib\\runpy.py\", line 197, in _run_module_as_main\n      return _run_code(code, main_globals, None,\n    File \"C:\\Users\\Usuario\\anaconda3\\lib\\runpy.py\", line 87, in _run_code\n      exec(code, run_globals)\n    File \"C:\\Users\\Usuario\\anaconda3\\lib\\site-packages\\ipykernel_launcher.py\", line 16, in <module>\n      app.launch_new_instance()\n    File \"C:\\Users\\Usuario\\anaconda3\\lib\\site-packages\\traitlets\\config\\application.py\", line 846, in launch_instance\n      app.start()\n    File \"C:\\Users\\Usuario\\anaconda3\\lib\\site-packages\\ipykernel\\kernelapp.py\", line 677, in start\n      self.io_loop.start()\n    File \"C:\\Users\\Usuario\\anaconda3\\lib\\site-packages\\tornado\\platform\\asyncio.py\", line 199, in start\n      self.asyncio_loop.run_forever()\n    File \"C:\\Users\\Usuario\\anaconda3\\lib\\asyncio\\base_events.py\", line 596, in run_forever\n      self._run_once()\n    File \"C:\\Users\\Usuario\\anaconda3\\lib\\asyncio\\base_events.py\", line 1890, in _run_once\n      handle._run()\n    File \"C:\\Users\\Usuario\\anaconda3\\lib\\asyncio\\events.py\", line 80, in _run\n      self._context.run(self._callback, *self._args)\n    File \"C:\\Users\\Usuario\\anaconda3\\lib\\site-packages\\ipykernel\\kernelbase.py\", line 457, in dispatch_queue\n      await self.process_one()\n    File \"C:\\Users\\Usuario\\anaconda3\\lib\\site-packages\\ipykernel\\kernelbase.py\", line 446, in process_one\n      await dispatch(*args)\n    File \"C:\\Users\\Usuario\\anaconda3\\lib\\site-packages\\ipykernel\\kernelbase.py\", line 353, in dispatch_shell\n      await result\n    File \"C:\\Users\\Usuario\\anaconda3\\lib\\site-packages\\ipykernel\\kernelbase.py\", line 648, in execute_request\n      reply_content = await reply_content\n    File \"C:\\Users\\Usuario\\anaconda3\\lib\\site-packages\\ipykernel\\ipkernel.py\", line 353, in do_execute\n      res = shell.run_cell(code, store_history=store_history, silent=silent)\n    File \"C:\\Users\\Usuario\\anaconda3\\lib\\site-packages\\ipykernel\\zmqshell.py\", line 533, in run_cell\n      return super(ZMQInteractiveShell, self).run_cell(*args, **kwargs)\n    File \"C:\\Users\\Usuario\\anaconda3\\lib\\site-packages\\IPython\\core\\interactiveshell.py\", line 2901, in run_cell\n      result = self._run_cell(\n    File \"C:\\Users\\Usuario\\anaconda3\\lib\\site-packages\\IPython\\core\\interactiveshell.py\", line 2947, in _run_cell\n      return runner(coro)\n    File \"C:\\Users\\Usuario\\anaconda3\\lib\\site-packages\\IPython\\core\\async_helpers.py\", line 68, in _pseudo_sync_runner\n      coro.send(None)\n    File \"C:\\Users\\Usuario\\anaconda3\\lib\\site-packages\\IPython\\core\\interactiveshell.py\", line 3172, in run_cell_async\n      has_raised = await self.run_ast_nodes(code_ast.body, cell_name,\n    File \"C:\\Users\\Usuario\\anaconda3\\lib\\site-packages\\IPython\\core\\interactiveshell.py\", line 3364, in run_ast_nodes\n      if (await self.run_code(code, result,  async_=asy)):\n    File \"C:\\Users\\Usuario\\anaconda3\\lib\\site-packages\\IPython\\core\\interactiveshell.py\", line 3444, in run_code\n      exec(code_obj, self.user_global_ns, self.user_ns)\n    File \"C:\\Users\\Usuario\\AppData\\Local\\Temp/ipykernel_19560/2906213625.py\", line 1, in <module>\n      cnn.fit(\n    File \"C:\\Users\\Usuario\\anaconda3\\lib\\site-packages\\keras\\utils\\traceback_utils.py\", line 64, in error_handler\n      return fn(*args, **kwargs)\n    File \"C:\\Users\\Usuario\\anaconda3\\lib\\site-packages\\keras\\engine\\training.py\", line 1409, in fit\n      tmp_logs = self.train_function(iterator)\n    File \"C:\\Users\\Usuario\\anaconda3\\lib\\site-packages\\keras\\engine\\training.py\", line 1051, in train_function\n      return step_function(self, iterator)\n    File \"C:\\Users\\Usuario\\anaconda3\\lib\\site-packages\\keras\\engine\\training.py\", line 1040, in step_function\n      outputs = model.distribute_strategy.run(run_step, args=(data,))\n    File \"C:\\Users\\Usuario\\anaconda3\\lib\\site-packages\\keras\\engine\\training.py\", line 1030, in run_step\n      outputs = model.train_step(data)\n    File \"C:\\Users\\Usuario\\anaconda3\\lib\\site-packages\\keras\\engine\\training.py\", line 889, in train_step\n      y_pred = self(x, training=True)\n    File \"C:\\Users\\Usuario\\anaconda3\\lib\\site-packages\\keras\\utils\\traceback_utils.py\", line 64, in error_handler\n      return fn(*args, **kwargs)\n    File \"C:\\Users\\Usuario\\anaconda3\\lib\\site-packages\\keras\\engine\\training.py\", line 490, in __call__\n      return super().__call__(*args, **kwargs)\n    File \"C:\\Users\\Usuario\\anaconda3\\lib\\site-packages\\keras\\utils\\traceback_utils.py\", line 64, in error_handler\n      return fn(*args, **kwargs)\n    File \"C:\\Users\\Usuario\\anaconda3\\lib\\site-packages\\keras\\engine\\base_layer.py\", line 1014, in __call__\n      outputs = call_fn(inputs, *args, **kwargs)\n    File \"C:\\Users\\Usuario\\anaconda3\\lib\\site-packages\\keras\\utils\\traceback_utils.py\", line 92, in error_handler\n      return fn(*args, **kwargs)\n    File \"C:\\Users\\Usuario\\anaconda3\\lib\\site-packages\\keras\\engine\\sequential.py\", line 374, in call\n      return super(Sequential, self).call(inputs, training=training, mask=mask)\n    File \"C:\\Users\\Usuario\\anaconda3\\lib\\site-packages\\keras\\engine\\functional.py\", line 458, in call\n      return self._run_internal_graph(\n    File \"C:\\Users\\Usuario\\anaconda3\\lib\\site-packages\\keras\\engine\\functional.py\", line 596, in _run_internal_graph\n      outputs = node.layer(*args, **kwargs)\n    File \"C:\\Users\\Usuario\\anaconda3\\lib\\site-packages\\keras\\utils\\traceback_utils.py\", line 64, in error_handler\n      return fn(*args, **kwargs)\n    File \"C:\\Users\\Usuario\\anaconda3\\lib\\site-packages\\keras\\engine\\base_layer.py\", line 1014, in __call__\n      outputs = call_fn(inputs, *args, **kwargs)\n    File \"C:\\Users\\Usuario\\anaconda3\\lib\\site-packages\\keras\\utils\\traceback_utils.py\", line 92, in error_handler\n      return fn(*args, **kwargs)\n    File \"C:\\Users\\Usuario\\anaconda3\\lib\\site-packages\\keras\\layers\\reshaping\\flatten.py\", line 98, in call\n      return tf.reshape(inputs, flattened_shape)\nNode: 'sequential_1/flatten/Reshape'\nInput to reshape is a tensor with 262144 values, but the requested shape requires a multiple of 25088\n\t [[{{node sequential_1/flatten/Reshape}}]] [Op:__inference_train_function_10279]",
     "output_type": "error",
     "traceback": [
      "\u001b[1;31m---------------------------------------------------------------------------\u001b[0m",
      "\u001b[1;31mInvalidArgumentError\u001b[0m                      Traceback (most recent call last)",
      "\u001b[1;32m~\\AppData\\Local\\Temp/ipykernel_19560/2906213625.py\u001b[0m in \u001b[0;36m<module>\u001b[1;34m\u001b[0m\n\u001b[1;32m----> 1\u001b[1;33m cnn.fit(\n\u001b[0m\u001b[0;32m      2\u001b[0m     \u001b[0mentrenamiento_generador\u001b[0m\u001b[1;33m,\u001b[0m\u001b[1;33m\u001b[0m\u001b[1;33m\u001b[0m\u001b[0m\n\u001b[0;32m      3\u001b[0m     \u001b[0msteps_per_epoch\u001b[0m\u001b[1;33m=\u001b[0m\u001b[0mpasos\u001b[0m\u001b[1;33m,\u001b[0m\u001b[1;33m\u001b[0m\u001b[1;33m\u001b[0m\u001b[0m\n\u001b[0;32m      4\u001b[0m     \u001b[0mepochs\u001b[0m\u001b[1;33m=\u001b[0m\u001b[0mepocas\u001b[0m\u001b[1;33m,\u001b[0m\u001b[1;33m\u001b[0m\u001b[1;33m\u001b[0m\u001b[0m\n\u001b[0;32m      5\u001b[0m     \u001b[0mvalidation_data\u001b[0m\u001b[1;33m=\u001b[0m\u001b[0mvalidacion_generador\u001b[0m\u001b[1;33m,\u001b[0m\u001b[1;33m\u001b[0m\u001b[1;33m\u001b[0m\u001b[0m\n",
      "\u001b[1;32m~\\anaconda3\\lib\\site-packages\\keras\\utils\\traceback_utils.py\u001b[0m in \u001b[0;36merror_handler\u001b[1;34m(*args, **kwargs)\u001b[0m\n\u001b[0;32m     65\u001b[0m     \u001b[1;32mexcept\u001b[0m \u001b[0mException\u001b[0m \u001b[1;32mas\u001b[0m \u001b[0me\u001b[0m\u001b[1;33m:\u001b[0m  \u001b[1;31m# pylint: disable=broad-except\u001b[0m\u001b[1;33m\u001b[0m\u001b[1;33m\u001b[0m\u001b[0m\n\u001b[0;32m     66\u001b[0m       \u001b[0mfiltered_tb\u001b[0m \u001b[1;33m=\u001b[0m \u001b[0m_process_traceback_frames\u001b[0m\u001b[1;33m(\u001b[0m\u001b[0me\u001b[0m\u001b[1;33m.\u001b[0m\u001b[0m__traceback__\u001b[0m\u001b[1;33m)\u001b[0m\u001b[1;33m\u001b[0m\u001b[1;33m\u001b[0m\u001b[0m\n\u001b[1;32m---> 67\u001b[1;33m       \u001b[1;32mraise\u001b[0m \u001b[0me\u001b[0m\u001b[1;33m.\u001b[0m\u001b[0mwith_traceback\u001b[0m\u001b[1;33m(\u001b[0m\u001b[0mfiltered_tb\u001b[0m\u001b[1;33m)\u001b[0m \u001b[1;32mfrom\u001b[0m \u001b[1;32mNone\u001b[0m\u001b[1;33m\u001b[0m\u001b[1;33m\u001b[0m\u001b[0m\n\u001b[0m\u001b[0;32m     68\u001b[0m     \u001b[1;32mfinally\u001b[0m\u001b[1;33m:\u001b[0m\u001b[1;33m\u001b[0m\u001b[1;33m\u001b[0m\u001b[0m\n\u001b[0;32m     69\u001b[0m       \u001b[1;32mdel\u001b[0m \u001b[0mfiltered_tb\u001b[0m\u001b[1;33m\u001b[0m\u001b[1;33m\u001b[0m\u001b[0m\n",
      "\u001b[1;32m~\\anaconda3\\lib\\site-packages\\tensorflow\\python\\eager\\execute.py\u001b[0m in \u001b[0;36mquick_execute\u001b[1;34m(op_name, num_outputs, inputs, attrs, ctx, name)\u001b[0m\n\u001b[0;32m     52\u001b[0m   \u001b[1;32mtry\u001b[0m\u001b[1;33m:\u001b[0m\u001b[1;33m\u001b[0m\u001b[1;33m\u001b[0m\u001b[0m\n\u001b[0;32m     53\u001b[0m     \u001b[0mctx\u001b[0m\u001b[1;33m.\u001b[0m\u001b[0mensure_initialized\u001b[0m\u001b[1;33m(\u001b[0m\u001b[1;33m)\u001b[0m\u001b[1;33m\u001b[0m\u001b[1;33m\u001b[0m\u001b[0m\n\u001b[1;32m---> 54\u001b[1;33m     tensors = pywrap_tfe.TFE_Py_Execute(ctx._handle, device_name, op_name,\n\u001b[0m\u001b[0;32m     55\u001b[0m                                         inputs, attrs, num_outputs)\n\u001b[0;32m     56\u001b[0m   \u001b[1;32mexcept\u001b[0m \u001b[0mcore\u001b[0m\u001b[1;33m.\u001b[0m\u001b[0m_NotOkStatusException\u001b[0m \u001b[1;32mas\u001b[0m \u001b[0me\u001b[0m\u001b[1;33m:\u001b[0m\u001b[1;33m\u001b[0m\u001b[1;33m\u001b[0m\u001b[0m\n",
      "\u001b[1;31mInvalidArgumentError\u001b[0m: Graph execution error:\n\nDetected at node 'sequential_1/flatten/Reshape' defined at (most recent call last):\n    File \"C:\\Users\\Usuario\\anaconda3\\lib\\runpy.py\", line 197, in _run_module_as_main\n      return _run_code(code, main_globals, None,\n    File \"C:\\Users\\Usuario\\anaconda3\\lib\\runpy.py\", line 87, in _run_code\n      exec(code, run_globals)\n    File \"C:\\Users\\Usuario\\anaconda3\\lib\\site-packages\\ipykernel_launcher.py\", line 16, in <module>\n      app.launch_new_instance()\n    File \"C:\\Users\\Usuario\\anaconda3\\lib\\site-packages\\traitlets\\config\\application.py\", line 846, in launch_instance\n      app.start()\n    File \"C:\\Users\\Usuario\\anaconda3\\lib\\site-packages\\ipykernel\\kernelapp.py\", line 677, in start\n      self.io_loop.start()\n    File \"C:\\Users\\Usuario\\anaconda3\\lib\\site-packages\\tornado\\platform\\asyncio.py\", line 199, in start\n      self.asyncio_loop.run_forever()\n    File \"C:\\Users\\Usuario\\anaconda3\\lib\\asyncio\\base_events.py\", line 596, in run_forever\n      self._run_once()\n    File \"C:\\Users\\Usuario\\anaconda3\\lib\\asyncio\\base_events.py\", line 1890, in _run_once\n      handle._run()\n    File \"C:\\Users\\Usuario\\anaconda3\\lib\\asyncio\\events.py\", line 80, in _run\n      self._context.run(self._callback, *self._args)\n    File \"C:\\Users\\Usuario\\anaconda3\\lib\\site-packages\\ipykernel\\kernelbase.py\", line 457, in dispatch_queue\n      await self.process_one()\n    File \"C:\\Users\\Usuario\\anaconda3\\lib\\site-packages\\ipykernel\\kernelbase.py\", line 446, in process_one\n      await dispatch(*args)\n    File \"C:\\Users\\Usuario\\anaconda3\\lib\\site-packages\\ipykernel\\kernelbase.py\", line 353, in dispatch_shell\n      await result\n    File \"C:\\Users\\Usuario\\anaconda3\\lib\\site-packages\\ipykernel\\kernelbase.py\", line 648, in execute_request\n      reply_content = await reply_content\n    File \"C:\\Users\\Usuario\\anaconda3\\lib\\site-packages\\ipykernel\\ipkernel.py\", line 353, in do_execute\n      res = shell.run_cell(code, store_history=store_history, silent=silent)\n    File \"C:\\Users\\Usuario\\anaconda3\\lib\\site-packages\\ipykernel\\zmqshell.py\", line 533, in run_cell\n      return super(ZMQInteractiveShell, self).run_cell(*args, **kwargs)\n    File \"C:\\Users\\Usuario\\anaconda3\\lib\\site-packages\\IPython\\core\\interactiveshell.py\", line 2901, in run_cell\n      result = self._run_cell(\n    File \"C:\\Users\\Usuario\\anaconda3\\lib\\site-packages\\IPython\\core\\interactiveshell.py\", line 2947, in _run_cell\n      return runner(coro)\n    File \"C:\\Users\\Usuario\\anaconda3\\lib\\site-packages\\IPython\\core\\async_helpers.py\", line 68, in _pseudo_sync_runner\n      coro.send(None)\n    File \"C:\\Users\\Usuario\\anaconda3\\lib\\site-packages\\IPython\\core\\interactiveshell.py\", line 3172, in run_cell_async\n      has_raised = await self.run_ast_nodes(code_ast.body, cell_name,\n    File \"C:\\Users\\Usuario\\anaconda3\\lib\\site-packages\\IPython\\core\\interactiveshell.py\", line 3364, in run_ast_nodes\n      if (await self.run_code(code, result,  async_=asy)):\n    File \"C:\\Users\\Usuario\\anaconda3\\lib\\site-packages\\IPython\\core\\interactiveshell.py\", line 3444, in run_code\n      exec(code_obj, self.user_global_ns, self.user_ns)\n    File \"C:\\Users\\Usuario\\AppData\\Local\\Temp/ipykernel_19560/2906213625.py\", line 1, in <module>\n      cnn.fit(\n    File \"C:\\Users\\Usuario\\anaconda3\\lib\\site-packages\\keras\\utils\\traceback_utils.py\", line 64, in error_handler\n      return fn(*args, **kwargs)\n    File \"C:\\Users\\Usuario\\anaconda3\\lib\\site-packages\\keras\\engine\\training.py\", line 1409, in fit\n      tmp_logs = self.train_function(iterator)\n    File \"C:\\Users\\Usuario\\anaconda3\\lib\\site-packages\\keras\\engine\\training.py\", line 1051, in train_function\n      return step_function(self, iterator)\n    File \"C:\\Users\\Usuario\\anaconda3\\lib\\site-packages\\keras\\engine\\training.py\", line 1040, in step_function\n      outputs = model.distribute_strategy.run(run_step, args=(data,))\n    File \"C:\\Users\\Usuario\\anaconda3\\lib\\site-packages\\keras\\engine\\training.py\", line 1030, in run_step\n      outputs = model.train_step(data)\n    File \"C:\\Users\\Usuario\\anaconda3\\lib\\site-packages\\keras\\engine\\training.py\", line 889, in train_step\n      y_pred = self(x, training=True)\n    File \"C:\\Users\\Usuario\\anaconda3\\lib\\site-packages\\keras\\utils\\traceback_utils.py\", line 64, in error_handler\n      return fn(*args, **kwargs)\n    File \"C:\\Users\\Usuario\\anaconda3\\lib\\site-packages\\keras\\engine\\training.py\", line 490, in __call__\n      return super().__call__(*args, **kwargs)\n    File \"C:\\Users\\Usuario\\anaconda3\\lib\\site-packages\\keras\\utils\\traceback_utils.py\", line 64, in error_handler\n      return fn(*args, **kwargs)\n    File \"C:\\Users\\Usuario\\anaconda3\\lib\\site-packages\\keras\\engine\\base_layer.py\", line 1014, in __call__\n      outputs = call_fn(inputs, *args, **kwargs)\n    File \"C:\\Users\\Usuario\\anaconda3\\lib\\site-packages\\keras\\utils\\traceback_utils.py\", line 92, in error_handler\n      return fn(*args, **kwargs)\n    File \"C:\\Users\\Usuario\\anaconda3\\lib\\site-packages\\keras\\engine\\sequential.py\", line 374, in call\n      return super(Sequential, self).call(inputs, training=training, mask=mask)\n    File \"C:\\Users\\Usuario\\anaconda3\\lib\\site-packages\\keras\\engine\\functional.py\", line 458, in call\n      return self._run_internal_graph(\n    File \"C:\\Users\\Usuario\\anaconda3\\lib\\site-packages\\keras\\engine\\functional.py\", line 596, in _run_internal_graph\n      outputs = node.layer(*args, **kwargs)\n    File \"C:\\Users\\Usuario\\anaconda3\\lib\\site-packages\\keras\\utils\\traceback_utils.py\", line 64, in error_handler\n      return fn(*args, **kwargs)\n    File \"C:\\Users\\Usuario\\anaconda3\\lib\\site-packages\\keras\\engine\\base_layer.py\", line 1014, in __call__\n      outputs = call_fn(inputs, *args, **kwargs)\n    File \"C:\\Users\\Usuario\\anaconda3\\lib\\site-packages\\keras\\utils\\traceback_utils.py\", line 92, in error_handler\n      return fn(*args, **kwargs)\n    File \"C:\\Users\\Usuario\\anaconda3\\lib\\site-packages\\keras\\layers\\reshaping\\flatten.py\", line 98, in call\n      return tf.reshape(inputs, flattened_shape)\nNode: 'sequential_1/flatten/Reshape'\nInput to reshape is a tensor with 262144 values, but the requested shape requires a multiple of 25088\n\t [[{{node sequential_1/flatten/Reshape}}]] [Op:__inference_train_function_10279]"
     ]
    }
   ],
   "source": [
    "cnn.fit(\n",
    "    entrenamiento_generador,\n",
    "    steps_per_epoch=pasos,\n",
    "    epochs=epocas,\n",
    "    validation_data=validacion_generador,\n",
    "    validation_steps=validation_steps)"
   ]
  },
  {
   "cell_type": "code",
   "execution_count": null,
   "id": "f592cc35",
   "metadata": {},
   "outputs": [],
   "source": [
    "target_dir = './modelo/'\n",
    "if not os.path.exists(target_dir):\n",
    "  os.mkdir(target_dir)\n",
    "cnn.save('./modelo/modeloVGG16.h5')\n",
    "cnn.save_weights('./modelo1/pesosVGG16.h5')"
   ]
  },
  {
   "cell_type": "code",
   "execution_count": null,
   "id": "688f769a",
   "metadata": {},
   "outputs": [],
   "source": []
  }
 ],
 "metadata": {
  "kernelspec": {
   "display_name": "Python 3 (ipykernel)",
   "language": "python",
   "name": "python3"
  },
  "language_info": {
   "codemirror_mode": {
    "name": "ipython",
    "version": 3
   },
   "file_extension": ".py",
   "mimetype": "text/x-python",
   "name": "python",
   "nbconvert_exporter": "python",
   "pygments_lexer": "ipython3",
   "version": "3.9.7"
  }
 },
 "nbformat": 4,
 "nbformat_minor": 5
}
